Workbook

Sheet Mulai
A1: Template Keuangan - Banyak Cicilan
A2: Tier 4: di atas Rp100.000.000 per bulan (di atas Rp1,2 miliar per tahun)
A4: Cara pakai (5 langkah)
A5: 1. Isi gaji bersihmu di sel kuning di bawah. Persentase alokasi menyesuaikan otomatis dengan gajimu.
A6: 2. Buka sheet 'Cicilan', timpa 3 baris contoh dengan cicilan/utangmu. Rasio dan urutan pelunasan terisi otomatis.
A7: 3. Catat setiap pemasukan dan pengeluaran di sheet 'Transaksi'.
A8: 4. Lihat hasilnya di sheet 'Dashboard'. Ganti bulan di sel B3 untuk melihat bulan lain.
A9: 5. Mau ubah persentase? Edit tabel 'Profil alokasi' di bagian bawah sheet ini.
A10: Warna: biru = boleh diisi/diubah, latar kuning = sel penting, hitam = otomatis (jangan dihapus).
A12: Isi di sini
A13: Gaji bersih per bulan | B13: 150000000 | C13: <- contoh, ganti dengan gajimu
A14: Penghasilan lain per bulan | B14: 0
A15: Total penghasilan per bulan | B15: =B13+B14 -> 150000000
A16: Total penghasilan per tahun | B16: =B15*12 -> 1800000000
A17: Tahun pencatatan | B17: 2026
A18: Tier template ini | B18: Tier 4: di atas Rp100.000.000 per bulan (di atas Rp1,2 miliar per tahun)
A20: Alokasi gajimu (otomatis dari tabel profil di bawah)
A21: Alokasi | B21: Persentase | C21: Nominal per bulan | D21: Nominal per tahun
A22: Cicilan & utang | B22: =INDEX($B$32:$B$33,$B$34) -> 0.2 | C22: =B22*$B$15 -> 30000000 | D22: =C22*12 -> 360000000
A23: Kebutuhan | B23: =INDEX($C$32:$C$33,$B$34) -> 0.15 | C23: =B23*$B$15 -> 22500000 | D23: =C23*12 -> 270000000
A24: Keinginan | B24: =INDEX($D$32:$D$33,$B$34) -> 0.2 | C24: =B24*$B$15 -> 30000000 | D24: =C24*12 -> 360000000
A25: Tabungan & investasi | B25: =INDEX($E$32:$E$33,$B$34) -> 0.45 | C25: =B25*$B$15 -> 67500000 | D25: =C25*12 -> 810000000
A26: Total | B26: =SUM(B22:B25) -> 1 | C26: =SUM(C22:C25) -> 150000000 | D26: =SUM(D22:D25) -> 1800000000
A27: Cek total persentase | B27: =IF(ROUND(B26,4)=1,"OK","Harus 100%") -> OK
A30: Profil alokasi menurut gaji (boleh diubah)
A31: Gaji sampai (per bulan) | B31: Cicilan & utang | C31: Kebutuhan | D31: Keinginan | E31: Tabungan & investasi
A32: 200000000 | B32: 0.2 | C32: 0.15 | D32: 0.2 | E32: 0.45
A33: 1000000000000 | B33: 0.15 | C33: 0.15 | D33: 0.2 | E33: 0.5
A34: Baris profil yang dipakai (otomatis) | B34: =MIN(COUNTIF($A$32:$A$33,"<"&$B$15)+1,2) -> 1
A36: Catatan asumsi:
A37: - Persentase adalah panduan umum (kerangka 50/30/20 yang disesuaikan menurut besar gaji), bukan hasil hitungan resmi dan bukan nasihat keuangan.
A38: - Program memilih baris profil pertama yang batas gajinya sama dengan atau di atas gajimu. Ubah angka biru untuk menyesuaikan.
A39: - Semua data tersimpan di file ini, di perangkatmu sendiri. Simpan salinan (backup) berkala.
A40: - Angka gaji, cicilan, dan saldo dana darurat di file ini hanya CONTOH.
A41: - Transaksi muat sekitar 1.000 baris. Kalau penuh atau ganti tahun, simpan salinan file dan mulai file baru.
A42: - Google Sheets: unggah file ke Google Drive, klik kanan, 'Buka dengan Google Sheets'.

Sheet Transaksi
A1: Transaksi
A2: Catat semua pemasukan dan pengeluaran di sini. Kolom hitam (F-H) terisi otomatis.
A3: Contoh pengisian (jangan diisi di baris ini):
A4: 46027 | B4: Pengeluaran | C4: Makan & belanja dapur | D4: Belanja mingguan di pasar (contoh) | E4: 150000
A5: Pemasukan: kategori boleh dikosongkan. Pengeluaran: pilih kategori dari daftar.
A6: Tanggal | B6: Jenis | C6: Kategori | D6: Keterangan | E6: Jumlah | F6: Bulan | G6: Tahun | H6: Kelompok
F7: =IF(A7="","",MONTH(A7)) | G7: =IF(A7="","",YEAR(A7)) | H7: =IF(OR(C7="",B7<>"Pengeluaran"),"",IFERROR(INDEX(Dashboard!$B$18:$B$39,MATCH(C7,Dashboard!$A$18:$A$39,0)),""))
F8: =IF(A8="","",MONTH(A8)) | G8: =IF(A8="","",YEAR(A8)) | H8: =IF(OR(C8="",B8<>"Pengeluaran"),"",IFERROR(INDEX(Dashboard!$B$18:$B$39,MATCH(C8,Dashboard!$A$18:$A$39,0)),""))
F9: =IF(A9="","",MONTH(A9)) | G9: =IF(A9="","",YEAR(A9)) | H9: =IF(OR(C9="",B9<>"Pengeluaran"),"",IFERROR(INDEX(Dashboard!$B$18:$B$39,MATCH(C9,Dashboard!$A$18:$A$39,0)),""))
F10: =IF(A10="","",MONTH(A10)) | G10: =IF(A10="","",YEAR(A10)) | H10: =IF(OR(C10="",B10<>"Pengeluaran"),"",IFERROR(INDEX(Dashboard!$B$18:$B$39,MATCH(C10,Dashboard!$A$18:$A$39,0)),""))
F11: =IF(A11="","",MONTH(A11)) | G11: =IF(A11="","",YEAR(A11)) | H11: =IF(OR(C11="",B11<>"Pengeluaran"),"",IFERROR(INDEX(Dashboard!$B$18:$B$39,MATCH(C11,Dashboard!$A$18:$A$39,0)),""))
F12: =IF(A12="","",MONTH(A12)) | G12: =IF(A12="","",YEAR(A12)) | H12: =IF(OR(C12="",B12<>"Pengeluaran"),"",IFERROR(INDEX(Dashboard!$B$18:$B$39,MATCH(C12,Dashboard!$A$18:$A$39,0)),""))
F13: =IF(A13="","",MONTH(A13)) | G13: =IF(A13="","",YEAR(A13)) | H13: =IF(OR(C13="",B13<>"Pengeluaran"),"",IFERROR(INDEX(Dashboard!$B$18:$B$39,MATCH(C13,Dashboard!$A$18:$A$39,0)),""))
F14: =IF(A14="","",MONTH(A14)) | G14: =IF(A14="","",YEAR(A14)) | H14: =IF(OR(C14="",B14<>"Pengeluaran"),"",IFERROR(INDEX(Dashboard!$B$18:$B$39,MATCH(C14,Dashboard!$A$18:$A$39,0)),""))
F15: =IF(A15="","",MONTH(A15)) | G15: =IF(A15="","",YEAR(A15)) | H15: =IF(OR(C15="",B15<>"Pengeluaran"),"",IFERROR(INDEX(Dashboard!$B$18:$B$39,MATCH(C15,Dashboard!$A$18:$A$39,0)),""))
F16: =IF(A16="","",MONTH(A16)) | G16: =IF(A16="","",YEAR(A16)) | H16: =IF(OR(C16="",B16<>"Pengeluaran"),"",IFERROR(INDEX(Dashboard!$B$18:$B$39,MATCH(C16,Dashboard!$A$18:$A$39,0)),""))
F17: =IF(A17="","",MONTH(A17)) | G17: =IF(A17="","",YEAR(A17)) | H17: =IF(OR(C17="",B17<>"Pengeluaran"),"",IFERROR(INDEX(Dashboard!$B$18:$B$39,MATCH(C17,Dashboard!$A$18:$A$39,0)),""))
F18: =IF(A18="","",MONTH(A18)) | G18: =IF(A18="","",YEAR(A18)) | H18: =IF(OR(C18="",B18<>"Pengeluaran"),"",IFERROR(INDEX(Dashboard!$B$18:$B$39,MATCH(C18,Dashboard!$A$18:$A$39,0)),""))
... F1006: =IF(A1006="","",MONTH(A1006)) | G1006: =IF(A1006="","",YEAR(A1006)) | H1006: =IF(OR(C1006="",B1006<>"Pengeluaran"),"",IFERROR(INDEX(Dashboard!$B$18:$B$39,MATCH(C1006,Dashboard!$A$18:$A$39,0)),""))

Sheet Dashboard
A1: Dashboard
A2: Semua hasil ada di sini dan terisi otomatis dari sheet 'Transaksi'.
A3: Bulan yang dilihat (1-12) | B3: 1 | C3: Tahun: | D3: =Mulai!$B$17 -> 2026
A5: 1. Ringkasan bulan ini per kelompok
A6: Kelompok | B6: Alokasi (%) | C6: Total porsi (cek) | D6: Anggaran per bulan | E6: Realisasi bulan ini | F6: Sisa | G6: % terpakai | H6: Cek porsi
A7: Cicilan & utang | B7: =INDEX(Mulai!$B$22:$B$25,MATCH(A7,Mulai!$A$22:$A$25,0)) -> 0.2 | C7: =SUMIFS($C$18:$C$39,$B$18:$B$39,A7) -> 1 | D7: =SUMIFS($D$18:$D$39,$B$18:$B$39,A7) -> 30000000 | E7: =SUMIFS($E$18:$E$39,$B$18:$B$39,A7) -> 0 | F7: =D7-E7 -> 30000000 | G7: =IF(D7=0,0,E7/D7) -> 0 | H7: =IF(ROUND(C7,4)=1,"OK","Porsi harus 100%") -> OK
A8: Kebutuhan | B8: =INDEX(Mulai!$B$22:$B$25,MATCH(A8,Mulai!$A$22:$A$25,0)) -> 0.15 | C8: =SUMIFS($C$18:$C$39,$B$18:$B$39,A8) -> 1 | D8: =SUMIFS($D$18:$D$39,$B$18:$B$39,A8) -> 22500000 | E8: =SUMIFS($E$18:$E$39,$B$18:$B$39,A8) -> 0 | F8: =D8-E8 -> 22500000 | G8: =IF(D8=0,0,E8/D8) -> 0 | H8: =IF(ROUND(C8,4)=1,"OK","Porsi harus 100%") -> OK
A9: Keinginan | B9: =INDEX(Mulai!$B$22:$B$25,MATCH(A9,Mulai!$A$22:$A$25,0)) -> 0.2 | C9: =SUMIFS($C$18:$C$39,$B$18:$B$39,A9) -> 1 | D9: =SUMIFS($D$18:$D$39,$B$18:$B$39,A9) -> 30000000 | E9: =SUMIFS($E$18:$E$39,$B$18:$B$39,A9) -> 0 | F9: =D9-E9 -> 30000000 | G9: =IF(D9=0,0,E9/D9) -> 0 | H9: =IF(ROUND(C9,4)=1,"OK","Porsi harus 100%") -> OK
A10: Tabungan & investasi | B10: =INDEX(Mulai!$B$22:$B$25,MATCH(A10,Mulai!$A$22:$A$25,0)) -> 0.45 | C10: =SUMIFS($C$18:$C$39,$B$18:$B$39,A10) -> 1 | D10: =SUMIFS($D$18:$D$39,$B$18:$B$39,A10) -> 67500000 | E10: =SUMIFS($E$18:$E$39,$B$18:$B$39,A10) -> 0 | F10: =D10-E10 -> 67500000 | G10: =IF(D10=0,0,E10/D10) -> 0 | H10: =IF(ROUND(C10,4)=1,"OK","Porsi harus 100%") -> OK
A12: Pemasukan bulan ini | D12: =SUMIFS(Transaksi!$E$7:$E$1006,Transaksi!$B$7:$B$1006,"Pemasukan",Transaksi!$F$7:$F$1006,$B$3,Transaksi!$G$7:$G$1006,Mulai!$B$17) -> 0
A13: Total keluar bulan ini (semua kelompok) | D13: =SUM(E7:E10) -> 0
A14: Sisa kas bulan ini | D14: =D12-D13 -> 0
A16: 2. Anggaran per kategori (angka biru = porsi, boleh diubah)
A17: Kategori | B17: Kelompok | C17: Porsi dalam kelompok | D17: Anggaran per bulan | E17: Realisasi bulan ini | F17: Sisa | G17: % terpakai | H17: Status
A18: Cicilan rumah (KPR) | B18: Cicilan & utang | C18: 0.67 | D18: =C18*INDEX(Mulai!$C$22:$C$25,MATCH(B18,Mulai!$A$22:$A$25,0)) -> 20100000 | E18: =SUMIFS(Transaksi!$E$7:$E$1006,Transaksi!$B$7:$B$1006,"Pengeluaran",Transaksi!$C$7:$C$1006,A18,Transaksi!$F$7:$F$1006,$B$3,Transaksi!$G$7:$G$1006,Mulai!$B$17) -> 0 | F18: =D18-E18 -> 20100000 | G18: =IF(D18=0,0,E18/D18) -> 0 | H18: =IF(D18=0,"-",IF(E18>D18,"Melebihi",IF(E18>=0.8*D18,"Hampir habis","Aman"))) -> Aman
A19: Cicilan kendaraan | B19: Cicilan & utang | C19: 0.27 | D19: =C19*INDEX(Mulai!$C$22:$C$25,MATCH(B19,Mulai!$A$22:$A$25,0)) -> 8100000 | E19: =SUMIFS(Transaksi!$E$7:$E$1006,Transaksi!$B$7:$B$1006,"Pengeluaran",Transaksi!$C$7:$C$1006,A19,Transaksi!$F$7:$F$1006,$B$3,Transaksi!$G$7:$G$1006,Mulai!$B$17) -> 0 | F19: =D19-E19 -> 8100000 | G19: =IF(D19=0,0,E19/D19) -> 0 | H19: =IF(D19=0,"-",IF(E19>D19,"Melebihi",IF(E19>=0.8*D19,"Hampir habis","Aman"))) -> Aman
A20: Kartu kredit & paylater | B20: Cicilan & utang | C20: 0.06 | D20: =C20*INDEX(Mulai!$C$22:$C$25,MATCH(B20,Mulai!$A$22:$A$25,0)) -> 1800000 | E20: =SUMIFS(Transaksi!$E$7:$E$1006,Transaksi!$B$7:$B$1006,"Pengeluaran",Transaksi!$C$7:$C$1006,A20,Transaksi!$F$7:$F$1006,$B$3,Transaksi!$G$7:$G$1006,Mulai!$B$17) -> 0 | F20: =D20-E20 -> 1800000 | G20: =IF(D20=0,0,E20/D20) -> 0 | H20: =IF(D20=0,"-",IF(E20>D20,"Melebihi",IF(E20>=0.8*D20,"Hampir habis","Aman"))) -> Aman
A21: Pinjaman lain | B21: Cicilan & utang | C21: 0 | D21: =C21*INDEX(Mulai!$C$22:$C$25,MATCH(B21,Mulai!$A$22:$A$25,0)) -> 0 | E21: =SUMIFS(Transaksi!$E$7:$E$1006,Transaksi!$B$7:$B$1006,"Pengeluaran",Transaksi!$C$7:$C$1006,A21,Transaksi!$F$7:$F$1006,$B$3,Transaksi!$G$7:$G$1006,Mulai!$B$17) -> 0 | F21: =D21-E21 -> 0 | G21: =IF(D21=0,0,E21/D21) -> 0 | H21: =IF(D21=0,"-",IF(E21>D21,"Melebihi",IF(E21>=0.8*D21,"Hampir habis","Aman"))) -> -
A22: Makan & belanja dapur | B22: Kebutuhan | C22: 0.3 | D22: =C22*INDEX(Mulai!$C$22:$C$25,MATCH(B22,Mulai!$A$22:$A$25,0)) -> 6750000 | E22: =SUMIFS(Transaksi!$E$7:$E$1006,Transaksi!$B$7:$B$1006,"Pengeluaran",Transaksi!$C$7:$C$1006,A22,Transaksi!$F$7:$F$1006,$B$3,Transaksi!$G$7:$G$1006,Mulai!$B$17) -> 0 | F22: =D22-E22 -> 6750000 | G22: =IF(D22=0,0,E22/D22) -> 0 | H22: =IF(D22=0,"-",IF(E22>D22,"Melebihi",IF(E22>=0.8*D22,"Hampir habis","Aman"))) -> Aman
A23: Sewa/tempat tinggal | B23: Kebutuhan | C23: 0.15 | D23: =C23*INDEX(Mulai!$C$22:$C$25,MATCH(B23,Mulai!$A$22:$A$25,0)) -> 3375000 | E23: =SUMIFS(Transaksi!$E$7:$E$1006,Transaksi!$B$7:$B$1006,"Pengeluaran",Transaksi!$C$7:$C$1006,A23,Transaksi!$F$7:$F$1006,$B$3,Transaksi!$G$7:$G$1006,Mulai!$B$17) -> 0 | F23: =D23-E23 -> 3375000 | G23: =IF(D23=0,0,E23/D23) -> 0 | H23: =IF(D23=0,"-",IF(E23>D23,"Melebihi",IF(E23>=0.8*D23,"Hampir habis","Aman"))) -> Aman
A24: Transport | B24: Kebutuhan | C24: 0.12 | D24: =C24*INDEX(Mulai!$C$22:$C$25,MATCH(B24,Mulai!$A$22:$A$25,0)) -> 2700000 | E24: =SUMIFS(Transaksi!$E$7:$E$1006,Transaksi!$B$7:$B$1006,"Pengeluaran",Transaksi!$C$7:$C$1006,A24,Transaksi!$F$7:$F$1006,$B$3,Transaksi!$G$7:$G$1006,Mulai!$B$17) -> 0 | F24: =D24-E24 -> 2700000 | G24: =IF(D24=0,0,E24/D24) -> 0 | H24: =IF(D24=0,"-",IF(E24>D24,"Melebihi",IF(E24>=0.8*D24,"Hampir habis","Aman"))) -> Aman
A25: Listrik, air & internet | B25: Kebutuhan | C25: 0.08 | D25: =C25*INDEX(Mulai!$C$22:$C$25,MATCH(B25,Mulai!$A$22:$A$25,0)) -> 1800000 | E25: =SUMIFS(Transaksi!$E$7:$E$1006,Transaksi!$B$7:$B$1006,"Pengeluaran",Transaksi!$C$7:$C$1006,A25,Transaksi!$F$7:$F$1006,$B$3,Transaksi!$G$7:$G$1006,Mulai!$B$17) -> 0 | F25: =D25-E25 -> 1800000 | G25: =IF(D25=0,0,E25/D25) -> 0 | H25: =IF(D25=0,"-",IF(E25>D25,"Melebihi",IF(E25>=0.8*D25,"Hampir habis","Aman"))) -> Aman
A26: Pulsa & data | B26: Kebutuhan | C26: 0.03 | D26: =C26*INDEX(Mulai!$C$22:$C$25,MATCH(B26,Mulai!$A$22:$A$25,0)) -> 675000 | E26: =SUMIFS(Transaksi!$E$7:$E$1006,Transaksi!$B$7:$B$1006,"Pengeluaran",Transaksi!$C$7:$C$1006,A26,Transaksi!$F$7:$F$1006,$B$3,Transaksi!$G$7:$G$1006,Mulai!$B$17) -> 0 | F26: =D26-E26 -> 675000 | G26: =IF(D26=0,0,E26/D26) -> 0 | H26: =IF(D26=0,"-",IF(E26>D26,"Melebihi",IF(E26>=0.8*D26,"Hampir habis","Aman"))) -> Aman
A27: Kesehatan | B27: Kebutuhan | C27: 0.07 | D27: =C27*INDEX(Mulai!$C$22:$C$25,MATCH(B27,Mulai!$A$22:$A$25,0)) -> 1575000 | E27: =SUMIFS(Transaksi!$E$7:$E$1006,Transaksi!$B$7:$B$1006,"Pengeluaran",Transaksi!$C$7:$C$1006,A27,Transaksi!$F$7:$F$1006,$B$3,Transaksi!$G$7:$G$1006,Mulai!$B$17) -> 0 | F27: =D27-E27 -> 1575000 | G27: =IF(D27=0,0,E27/D27) -> 0 | H27: =IF(D27=0,"-",IF(E27>D27,"Melebihi",IF(E27>=0.8*D27,"Hampir habis","Aman"))) -> Aman
A28: Pendidikan | B28: Kebutuhan | C28: 0.08 | D28: =C28*INDEX(Mulai!$C$22:$C$25,MATCH(B28,Mulai!$A$22:$A$25,0)) -> 1800000 | E28: =SUMIFS(Transaksi!$E$7:$E$1006,Transaksi!$B$7:$B$1006,"Pengeluaran",Transaksi!$C$7:$C$1006,A28,Transaksi!$F$7:$F$1006,$B$3,Transaksi!$G$7:$G$1006,Mulai!$B$17) -> 0 | F28: =D28-E28 -> 1800000 | G28: =IF(D28=0,0,E28/D28) -> 0 | H28: =IF(D28=0,"-",IF(E28>D28,"Melebihi",IF(E28>=0.8*D28,"Hampir habis","Aman"))) -> Aman
A29: Asuransi | B29: Kebutuhan | C29: 0.06 | D29: =C29*INDEX(Mulai!$C$22:$C$25,MATCH(B29,Mulai!$A$22:$A$25,0)) -> 1350000 | E29: =SUMIFS(Transaksi!$E$7:$E$1006,Transaksi!$B$7:$B$1006,"Pengeluaran",Transaksi!$C$7:$C$1006,A29,Transaksi!$F$7:$F$1006,$B$3,Transaksi!$G$7:$G$1006,Mulai!$B$17) -> 0 | F29: =D29-E29 -> 1350000 | G29: =IF(D29=0,0,E29/D29) -> 0 | H29: =IF(D29=0,"-",IF(E29>D29,"Melebihi",IF(E29>=0.8*D29,"Hampir habis","Aman"))) -> Aman
... A39: Tabungan tujuan | B39: Tabungan & investasi | C39: 0.2 | D39: =C39*INDEX(Mulai!$C$22:$C$25,MATCH(B39,Mulai!$A$22:$A$25,0)) -> 13500000 | E39: =SUMIFS(Transaksi!$E$7:$E$1006,Transaksi!$B$7:$B$1006,"Pengeluaran",Transaksi!$C$7:$C$1006,A39,Transaksi!$F$7:$F$1006,$B$3,Transaksi!$G$7:$G$1006,Mulai!$B$17) -> 0 | F39: =D39-E39 -> 13500000 | G39: =IF(D39=0,0,E39/D39) -> 0 | H39: =IF(D39=0,"-",IF(E39>D39,"Melebihi",IF(E39>=0.8*D39,"Hampir habis","Aman"))) -> Aman
A42: 3. Ringkasan tahunan
A43: Bulan | B43: Pemasukan | C43: Cicilan & utang | D43: Kebutuhan | E43: Keinginan | F43: Tabungan & investasi | G43: Total keluar | H43: Sisa kas | I43: Rasio tabungan
A44: Januari | B44: =SUMIFS(Transaksi!$E$7:$E$1006,Transaksi!$B$7:$B$1006,"Pemasukan",Transaksi!$F$7:$F$1006,1,Transaksi!$G$7:$G$1006,Mulai!$B$17) -> 0 | C44: =SUMIFS(Transaksi!$E$7:$E$1006,Transaksi!$B$7:$B$1006,"Pengeluaran",Transaksi!$H$7:$H$1006,C$43,Transaksi!$F$7:$F$1006,1,Transaksi!$G$7:$G$1006,Mulai!$B$17) -> 0 | D44: =SUMIFS(Transaksi!$E$7:$E$1006,Transaksi!$B$7:$B$1006,"Pengeluaran",Transaksi!$H$7:$H$1006,D$43,Transaksi!$F$7:$F$1006,1,Transaksi!$G$7:$G$1006,Mulai!$B$17) -> 0 | E44: =SUMIFS(Transaksi!$E$7:$E$1006,Transaksi!$B$7:$B$1006,"Pengeluaran",Transaksi!$H$7:$H$1006,E$43,Transaksi!$F$7:$F$1006,1,Transaksi!$G$7:$G$1006,Mulai!$B$17) -> 0 | F44: =SUMIFS(Transaksi!$E$7:$E$1006,Transaksi!$B$7:$B$1006,"Pengeluaran",Transaksi!$H$7:$H$1006,F$43,Transaksi!$F$7:$F$1006,1,Transaksi!$G$7:$G$1006,Mulai!$B$17) -> 0 | G44: =SUM(C44:F44) -> 0 | H44: =B44-G44 -> 0 | I44: =IF(B44=0,0,F44/B44) -> 0
A45: Februari | B45: =SUMIFS(Transaksi!$E$7:$E$1006,Transaksi!$B$7:$B$1006,"Pemasukan",Transaksi!$F$7:$F$1006,2,Transaksi!$G$7:$G$1006,Mulai!$B$17) -> 0 | C45: =SUMIFS(Transaksi!$E$7:$E$1006,Transaksi!$B$7:$B$1006,"Pengeluaran",Transaksi!$H$7:$H$1006,C$43,Transaksi!$F$7:$F$1006,2,Transaksi!$G$7:$G$1006,Mulai!$B$17) -> 0 | D45: =SUMIFS(Transaksi!$E$7:$E$1006,Transaksi!$B$7:$B$1006,"Pengeluaran",Transaksi!$H$7:$H$1006,D$43,Transaksi!$F$7:$F$1006,2,Transaksi!$G$7:$G$1006,Mulai!$B$17) -> 0 | E45: =SUMIFS(Transaksi!$E$7:$E$1006,Transaksi!$B$7:$B$1006,"Pengeluaran",Transaksi!$H$7:$H$1006,E$43,Transaksi!$F$7:$F$1006,2,Transaksi!$G$7:$G$1006,Mulai!$B$17) -> 0 | F45: =SUMIFS(Transaksi!$E$7:$E$1006,Transaksi!$B$7:$B$1006,"Pengeluaran",Transaksi!$H$7:$H$1006,F$43,Transaksi!$F$7:$F$1006,2,Transaksi!$G$7:$G$1006,Mulai!$B$17) -> 0 | G45: =SUM(C45:F45) -> 0 | H45: =B45-G45 -> 0 | I45: =IF(B45=0,0,F45/B45) -> 0
A46: Maret | B46: =SUMIFS(Transaksi!$E$7:$E$1006,Transaksi!$B$7:$B$1006,"Pemasukan",Transaksi!$F$7:$F$1006,3,Transaksi!$G$7:$G$1006,Mulai!$B$17) -> 0 | C46: =SUMIFS(Transaksi!$E$7:$E$1006,Transaksi!$B$7:$B$1006,"Pengeluaran",Transaksi!$H$7:$H$1006,C$43,Transaksi!$F$7:$F$1006,3,Transaksi!$G$7:$G$1006,Mulai!$B$17) -> 0 | D46: =SUMIFS(Transaksi!$E$7:$E$1006,Transaksi!$B$7:$B$1006,"Pengeluaran",Transaksi!$H$7:$H$1006,D$43,Transaksi!$F$7:$F$1006,3,Transaksi!$G$7:$G$1006,Mulai!$B$17) -> 0 | E46: =SUMIFS(Transaksi!$E$7:$E$1006,Transaksi!$B$7:$B$1006,"Pengeluaran",Transaksi!$H$7:$H$1006,E$43,Transaksi!$F$7:$F$1006,3,Transaksi!$G$7:$G$1006,Mulai!$B$17) -> 0 | F46: =SUMIFS(Transaksi!$E$7:$E$1006,Transaksi!$B$7:$B$1006,"Pengeluaran",Transaksi!$H$7:$H$1006,F$43,Transaksi!$F$7:$F$1006,3,Transaksi!$G$7:$G$1006,Mulai!$B$17) -> 0 | G46: =SUM(C46:F46) -> 0 | H46: =B46-G46 -> 0 | I46: =IF(B46=0,0,F46/B46) -> 0
A47: April | B47: =SUMIFS(Transaksi!$E$7:$E$1006,Transaksi!$B$7:$B$1006,"Pemasukan",Transaksi!$F$7:$F$1006,4,Transaksi!$G$7:$G$1006,Mulai!$B$17) -> 0 | C47: =SUMIFS(Transaksi!$E$7:$E$1006,Transaksi!$B$7:$B$1006,"Pengeluaran",Transaksi!$H$7:$H$1006,C$43,Transaksi!$F$7:$F$1006,4,Transaksi!$G$7:$G$1006,Mulai!$B$17) -> 0 | D47: =SUMIFS(Transaksi!$E$7:$E$1006,Transaksi!$B$7:$B$1006,"Pengeluaran",Transaksi!$H$7:$H$1006,D$43,Transaksi!$F$7:$F$1006,4,Transaksi!$G$7:$G$1006,Mulai!$B$17) -> 0 | E47: =SUMIFS(Transaksi!$E$7:$E$1006,Transaksi!$B$7:$B$1006,"Pengeluaran",Transaksi!$H$7:$H$1006,E$43,Transaksi!$F$7:$F$1006,4,Transaksi!$G$7:$G$1006,Mulai!$B$17) -> 0 | F47: =SUMIFS(Transaksi!$E$7:$E$1006,Transaksi!$B$7:$B$1006,"Pengeluaran",Transaksi!$H$7:$H$1006,F$43,Transaksi!$F$7:$F$1006,4,Transaksi!$G$7:$G$1006,Mulai!$B$17) -> 0 | G47: =SUM(C47:F47) -> 0 | H47: =B47-G47 -> 0 | I47: =IF(B47=0,0,F47/B47) -> 0
A48: Mei | B48: =SUMIFS(Transaksi!$E$7:$E$1006,Transaksi!$B$7:$B$1006,"Pemasukan",Transaksi!$F$7:$F$1006,5,Transaksi!$G$7:$G$1006,Mulai!$B$17) -> 0 | C48: =SUMIFS(Transaksi!$E$7:$E$1006,Transaksi!$B$7:$B$1006,"Pengeluaran",Transaksi!$H$7:$H$1006,C$43,Transaksi!$F$7:$F$1006,5,Transaksi!$G$7:$G$1006,Mulai!$B$17) -> 0 | D48: =SUMIFS(Transaksi!$E$7:$E$1006,Transaksi!$B$7:$B$1006,"Pengeluaran",Transaksi!$H$7:$H$1006,D$43,Transaksi!$F$7:$F$1006,5,Transaksi!$G$7:$G$1006,Mulai!$B$17) -> 0 | E48: =SUMIFS(Transaksi!$E$7:$E$1006,Transaksi!$B$7:$B$1006,"Pengeluaran",Transaksi!$H$7:$H$1006,E$43,Transaksi!$F$7:$F$1006,5,Transaksi!$G$7:$G$1006,Mulai!$B$17) -> 0 | F48: =SUMIFS(Transaksi!$E$7:$E$1006,Transaksi!$B$7:$B$1006,"Pengeluaran",Transaksi!$H$7:$H$1006,F$43,Transaksi!$F$7:$F$1006,5,Transaksi!$G$7:$G$1006,Mulai!$B$17) -> 0 | G48: =SUM(C48:F48) -> 0 | H48: =B48-G48 -> 0 | I48: =IF(B48=0,0,F48/B48) -> 0
A49: Juni | B49: =SUMIFS(Transaksi!$E$7:$E$1006,Transaksi!$B$7:$B$1006,"Pemasukan",Transaksi!$F$7:$F$1006,6,Transaksi!$G$7:$G$1006,Mulai!$B$17) -> 0 | C49: =SUMIFS(Transaksi!$E$7:$E$1006,Transaksi!$B$7:$B$1006,"Pengeluaran",Transaksi!$H$7:$H$1006,C$43,Transaksi!$F$7:$F$1006,6,Transaksi!$G$7:$G$1006,Mulai!$B$17) -> 0 | D49: =SUMIFS(Transaksi!$E$7:$E$1006,Transaksi!$B$7:$B$1006,"Pengeluaran",Transaksi!$H$7:$H$1006,D$43,Transaksi!$F$7:$F$1006,6,Transaksi!$G$7:$G$1006,Mulai!$B$17) -> 0 | E49: =SUMIFS(Transaksi!$E$7:$E$1006,Transaksi!$B$7:$B$1006,"Pengeluaran",Transaksi!$H$7:$H$1006,E$43,Transaksi!$F$7:$F$1006,6,Transaksi!$G$7:$G$1006,Mulai!$B$17) -> 0 | F49: =SUMIFS(Transaksi!$E$7:$E$1006,Transaksi!$B$7:$B$1006,"Pengeluaran",Transaksi!$H$7:$H$1006,F$43,Transaksi!$F$7:$F$1006,6,Transaksi!$G$7:$G$1006,Mulai!$B$17) -> 0 | G49: =SUM(C49:F49) -> 0 | H49: =B49-G49 -> 0 | I49: =IF(B49=0,0,F49/B49) -> 0
A50: Juli | B50: =SUMIFS(Transaksi!$E$7:$E$1006,Transaksi!$B$7:$B$1006,"Pemasukan",Transaksi!$F$7:$F$1006,7,Transaksi!$G$7:$G$1006,Mulai!$B$17) -> 0 | C50: =SUMIFS(Transaksi!$E$7:$E$1006,Transaksi!$B$7:$B$1006,"Pengeluaran",Transaksi!$H$7:$H$1006,C$43,Transaksi!$F$7:$F$1006,7,Transaksi!$G$7:$G$1006,Mulai!$B$17) -> 0 | D50: =SUMIFS(Transaksi!$E$7:$E$1006,Transaksi!$B$7:$B$1006,"Pengeluaran",Transaksi!$H$7:$H$1006,D$43,Transaksi!$F$7:$F$1006,7,Transaksi!$G$7:$G$1006,Mulai!$B$17) -> 0 | E50: =SUMIFS(Transaksi!$E$7:$E$1006,Transaksi!$B$7:$B$1006,"Pengeluaran",Transaksi!$H$7:$H$1006,E$43,Transaksi!$F$7:$F$1006,7,Transaksi!$G$7:$G$1006,Mulai!$B$17) -> 0 | F50: =SUMIFS(Transaksi!$E$7:$E$1006,Transaksi!$B$7:$B$1006,"Pengeluaran",Transaksi!$H$7:$H$1006,F$43,Transaksi!$F$7:$F$1006,7,Transaksi!$G$7:$G$1006,Mulai!$B$17) -> 0 | G50: =SUM(C50:F50) -> 0 | H50: =B50-G50 -> 0 | I50: =IF(B50=0,0,F50/B50) -> 0
A51: Agustus | B51: =SUMIFS(Transaksi!$E$7:$E$1006,Transaksi!$B$7:$B$1006,"Pemasukan",Transaksi!$F$7:$F$1006,8,Transaksi!$G$7:$G$1006,Mulai!$B$17) -> 0 | C51: =SUMIFS(Transaksi!$E$7:$E$1006,Transaksi!$B$7:$B$1006,"Pengeluaran",Transaksi!$H$7:$H$1006,C$43,Transaksi!$F$7:$F$1006,8,Transaksi!$G$7:$G$1006,Mulai!$B$17) -> 0 | D51: =SUMIFS(Transaksi!$E$7:$E$1006,Transaksi!$B$7:$B$1006,"Pengeluaran",Transaksi!$H$7:$H$1006,D$43,Transaksi!$F$7:$F$1006,8,Transaksi!$G$7:$G$1006,Mulai!$B$17) -> 0 | E51: =SUMIFS(Transaksi!$E$7:$E$1006,Transaksi!$B$7:$B$1006,"Pengeluaran",Transaksi!$H$7:$H$1006,E$43,Transaksi!$F$7:$F$1006,8,Transaksi!$G$7:$G$1006,Mulai!$B$17) -> 0 | F51: =SUMIFS(Transaksi!$E$7:$E$1006,Transaksi!$B$7:$B$1006,"Pengeluaran",Transaksi!$H$7:$H$1006,F$43,Transaksi!$F$7:$F$1006,8,Transaksi!$G$7:$G$1006,Mulai!$B$17) -> 0 | G51: =SUM(C51:F51) -> 0 | H51: =B51-G51 -> 0 | I51: =IF(B51=0,0,F51/B51) -> 0
A52: September | B52: =SUMIFS(Transaksi!$E$7:$E$1006,Transaksi!$B$7:$B$1006,"Pemasukan",Transaksi!$F$7:$F$1006,9,Transaksi!$G$7:$G$1006,Mulai!$B$17) -> 0 | C52: =SUMIFS(Transaksi!$E$7:$E$1006,Transaksi!$B$7:$B$1006,"Pengeluaran",Transaksi!$H$7:$H$1006,C$43,Transaksi!$F$7:$F$1006,9,Transaksi!$G$7:$G$1006,Mulai!$B$17) -> 0 | D52: =SUMIFS(Transaksi!$E$7:$E$1006,Transaksi!$B$7:$B$1006,"Pengeluaran",Transaksi!$H$7:$H$1006,D$43,Transaksi!$F$7:$F$1006,9,Transaksi!$G$7:$G$1006,Mulai!$B$17) -> 0 | E52: =SUMIFS(Transaksi!$E$7:$E$1006,Transaksi!$B$7:$B$1006,"Pengeluaran",Transaksi!$H$7:$H$1006,E$43,Transaksi!$F$7:$F$1006,9,Transaksi!$G$7:$G$1006,Mulai!$B$17) -> 0 | F52: =SUMIFS(Transaksi!$E$7:$E$1006,Transaksi!$B$7:$B$1006,"Pengeluaran",Transaksi!$H$7:$H$1006,F$43,Transaksi!$F$7:$F$1006,9,Transaksi!$G$7:$G$1006,Mulai!$B$17) -> 0 | G52: =SUM(C52:F52) -> 0 | H52: =B52-G52 -> 0 | I52: =IF(B52=0,0,F52/B52) -> 0
A53: Oktober | B53: =SUMIFS(Transaksi!$E$7:$E$1006,Transaksi!$B$7:$B$1006,"Pemasukan",Transaksi!$F$7:$F$1006,10,Transaksi!$G$7:$G$1006,Mulai!$B$17) -> 0 | C53: =SUMIFS(Transaksi!$E$7:$E$1006,Transaksi!$B$7:$B$1006,"Pengeluaran",Transaksi!$H$7:$H$1006,C$43,Transaksi!$F$7:$F$1006,10,Transaksi!$G$7:$G$1006,Mulai!$B$17) -> 0 | D53: =SUMIFS(Transaksi!$E$7:$E$1006,Transaksi!$B$7:$B$1006,"Pengeluaran",Transaksi!$H$7:$H$1006,D$43,Transaksi!$F$7:$F$1006,10,Transaksi!$G$7:$G$1006,Mulai!$B$17) -> 0 | E53: =SUMIFS(Transaksi!$E$7:$E$1006,Transaksi!$B$7:$B$1006,"Pengeluaran",Transaksi!$H$7:$H$1006,E$43,Transaksi!$F$7:$F$1006,10,Transaksi!$G$7:$G$1006,Mulai!$B$17) -> 0 | F53: =SUMIFS(Transaksi!$E$7:$E$1006,Transaksi!$B$7:$B$1006,"Pengeluaran",Transaksi!$H$7:$H$1006,F$43,Transaksi!$F$7:$F$1006,10,Transaksi!$G$7:$G$1006,Mulai!$B$17) -> 0 | G53: =SUM(C53:F53) -> 0 | H53: =B53-G53 -> 0 | I53: =IF(B53=0,0,F53/B53) -> 0
A54: November | B54: =SUMIFS(Transaksi!$E$7:$E$1006,Transaksi!$B$7:$B$1006,"Pemasukan",Transaksi!$F$7:$F$1006,11,Transaksi!$G$7:$G$1006,Mulai!$B$17) -> 0 | C54: =SUMIFS(Transaksi!$E$7:$E$1006,Transaksi!$B$7:$B$1006,"Pengeluaran",Transaksi!$H$7:$H$1006,C$43,Transaksi!$F$7:$F$1006,11,Transaksi!$G$7:$G$1006,Mulai!$B$17) -> 0 | D54: =SUMIFS(Transaksi!$E$7:$E$1006,Transaksi!$B$7:$B$1006,"Pengeluaran",Transaksi!$H$7:$H$1006,D$43,Transaksi!$F$7:$F$1006,11,Transaksi!$G$7:$G$1006,Mulai!$B$17) -> 0 | E54: =SUMIFS(Transaksi!$E$7:$E$1006,Transaksi!$B$7:$B$1006,"Pengeluaran",Transaksi!$H$7:$H$1006,E$43,Transaksi!$F$7:$F$1006,11,Transaksi!$G$7:$G$1006,Mulai!$B$17) -> 0 | F54: =SUMIFS(Transaksi!$E$7:$E$1006,Transaksi!$B$7:$B$1006,"Pengeluaran",Transaksi!$H$7:$H$1006,F$43,Transaksi!$F$7:$F$1006,11,Transaksi!$G$7:$G$1006,Mulai!$B$17) -> 0 | G54: =SUM(C54:F54) -> 0 | H54: =B54-G54 -> 0 | I54: =IF(B54=0,0,F54/B54) -> 0
...

Sheet Cicilan
A1: Cicilan
A2: Isi daftar cicilan/utangmu. 3 baris pertama adalah CONTOH, timpa dengan datamu.
A4: 1. Daftar cicilan
A5: Nama cicilan | B5: Jenis | C5: Sisa pokok (Rp) | D5: Bunga per tahun | E5: Cicilan per bulan (Rp) | F5: Sisa tenor (bulan) | G5: Jatuh tempo (tanggal) | H5: Urutan Avalanche | I5: Urutan Snowball
A6: KPR rumah | B6: KPR | C6: 2000000000 | D6: 7 | E6: 20000000 | F6: 120 | G6: 1 | H6: =IF(A6="","",RANK(D6,$D$6:$D$15,0)+COUNTIF($D$6:D6,D6)-1) -> 3 | I6: =IF(A6="","",RANK(C6,$C$6:$C$15,1)+COUNTIF($C$6:C6,C6)-1) -> 3
A7: Mobil | B7: Kendaraan | C7: 240000000 | D7: 8 | E7: 8000000 | F7: 30 | G7: 5 | H7: =IF(A7="","",RANK(D7,$D$6:$D$15,0)+COUNTIF($D$6:D7,D7)-1) -> 2 | I7: =IF(A7="","",RANK(C7,$C$6:$C$15,1)+COUNTIF($C$6:C7,C7)-1) -> 2
A8: Kartu kredit | B8: Kartu kredit | C8: 10000000 | D8: 24 | E8: 2000000 | F8: 5 | G8: 15 | H8: =IF(A8="","",RANK(D8,$D$6:$D$15,0)+COUNTIF($D$6:D8,D8)-1) -> 1 | I8: =IF(A8="","",RANK(C8,$C$6:$C$15,1)+COUNTIF($C$6:C8,C8)-1) -> 1
H9: =IF(A9="","",RANK(D9,$D$6:$D$15,0)+COUNTIF($D$6:D9,D9)-1) | I9: =IF(A9="","",RANK(C9,$C$6:$C$15,1)+COUNTIF($C$6:C9,C9)-1)
H10: =IF(A10="","",RANK(D10,$D$6:$D$15,0)+COUNTIF($D$6:D10,D10)-1) | I10: =IF(A10="","",RANK(C10,$C$6:$C$15,1)+COUNTIF($C$6:C10,C10)-1)
H11: =IF(A11="","",RANK(D11,$D$6:$D$15,0)+COUNTIF($D$6:D11,D11)-1) | I11: =IF(A11="","",RANK(C11,$C$6:$C$15,1)+COUNTIF($C$6:C11,C11)-1)
H12: =IF(A12="","",RANK(D12,$D$6:$D$15,0)+COUNTIF($D$6:D12,D12)-1) | I12: =IF(A12="","",RANK(C12,$C$6:$C$15,1)+COUNTIF($C$6:C12,C12)-1)
H13: =IF(A13="","",RANK(D13,$D$6:$D$15,0)+COUNTIF($D$6:D13,D13)-1) | I13: =IF(A13="","",RANK(C13,$C$6:$C$15,1)+COUNTIF($C$6:C13,C13)-1)
H14: =IF(A14="","",RANK(D14,$D$6:$D$15,0)+COUNTIF($D$6:D14,D14)-1) | I14: =IF(A14="","",RANK(C14,$C$6:$C$15,1)+COUNTIF($C$6:C14,C14)-1)
H15: =IF(A15="","",RANK(D15,$D$6:$D$15,0)+COUNTIF($D$6:D15,D15)-1) | I15: =IF(A15="","",RANK(C15,$C$6:$C$15,1)+COUNTIF($C$6:C15,C15)-1)
A16: Total | C16: =SUM(C6:C15) -> 2250000000 | E16: =SUM(E6:E15) -> 30000000 | F16: =MAX(F6:F15) -> 120
A19: 2. Rasio cicilan dan status
A20: Total cicilan per bulan | B20: =E16 -> 30000000
A21: Total penghasilan per bulan | B21: =Mulai!$B$15 -> 150000000
A22: Rasio cicilan terhadap penghasilan | B22: =IF(B21=0,0,B20/B21) -> 0.2
A23: Batas aman rasio cicilan | B23: 0.3
A24: Status | B24: =IF(B22<=B23,"Aman",IF(B22<=B23+0.1,"Waspada","Berat")) -> Aman
A25: Total sisa pokok utang | B25: =C16 -> 2250000000
A26: Cicilan terlama (bulan) | B26: =F16 -> 120
A27: Ruang cicilan tersisa per bulan (sampai batas aman) | B27: =MAX(0,B23*B21-B20) -> 15000000
A29: 3. Urutan pelunasan
A30: Urutan ke- | B30: Avalanche (bunga tertinggi dulu) | C30: Snowball (sisa pokok terkecil dulu)
A31: 1 | B31: =IFERROR(INDEX($A$6:$A$15,MATCH(1,$H$6:$H$15,0)),"") -> Kartu kredit | C31: =IFERROR(INDEX($A$6:$A$15,MATCH(1,$I$6:$I$15,0)),"") -> Kartu kredit
A32: 2 | B32: =IFERROR(INDEX($A$6:$A$15,MATCH(2,$H$6:$H$15,0)),"") -> Mobil | C32: =IFERROR(INDEX($A$6:$A$15,MATCH(2,$I$6:$I$15,0)),"") -> Mobil
A33: 3 | B33: =IFERROR(INDEX($A$6:$A$15,MATCH(3,$H$6:$H$15,0)),"") -> KPR rumah | C33: =IFERROR(INDEX($A$6:$A$15,MATCH(3,$I$6:$I$15,0)),"") -> KPR rumah
A34: 4 | B34: =IFERROR(INDEX($A$6:$A$15,MATCH(4,$H$6:$H$15,0)),"") | C34: =IFERROR(INDEX($A$6:$A$15,MATCH(4,$I$6:$I$15,0)),"")
A35: 5 | B35: =IFERROR(INDEX($A$6:$A$15,MATCH(5,$H$6:$H$15,0)),"") | C35: =IFERROR(INDEX($A$6:$A$15,MATCH(5,$I$6:$I$15,0)),"")
A36: 6 | B36: =IFERROR(INDEX($A$6:$A$15,MATCH(6,$H$6:$H$15,0)),"") | C36: =IFERROR(INDEX($A$6:$A$15,MATCH(6,$I$6:$I$15,0)),"")
A37: 7 | B37: =IFERROR(INDEX($A$6:$A$15,MATCH(7,$H$6:$H$15,0)),"") | C37: =IFERROR(INDEX($A$6:$A$15,MATCH(7,$I$6:$I$15,0)),"")
A38: 8 | B38: =IFERROR(INDEX($A$6:$A$15,MATCH(8,$H$6:$H$15,0)),"") | C38: =IFERROR(INDEX($A$6:$A$15,MATCH(8,$I$6:$I$15,0)),"")
A39: 9 | B39: =IFERROR(INDEX($A$6:$A$15,MATCH(9,$H$6:$H$15,0)),"") | C39: =IFERROR(INDEX($A$6:$A$15,MATCH(9,$I$6:$I$15,0)),"")
A40: 10 | B40: =IFERROR(INDEX($A$6:$A$15,MATCH(10,$H$6:$H$15,0)),"") | C40: =IFERROR(INDEX($A$6:$A$15,MATCH(10,$I$6:$I$15,0)),"")
A42: Asumsi: batas aman 30% adalah pedoman umum (bukan aturan resmi). Ubah di sel kuning kalau perlu.
A43: Status: Aman = rasio sampai batas; Waspada = sampai 10 poin di atas batas; Berat = lebih dari itu.
A44: Kalau status Waspada atau Berat, tunda cicilan baru dan fokus melunasi dulu.
A45: Avalanche paling hemat bunga; Snowball memberi rasa progres karena utang kecil lunas lebih cepat.
...
